Workbook

Sheet summary
A1: Metric and indicator reference | B1: Metric / Indicator | C1: Question format | D1: Evidence Required | E1: Policy dates required
B2: SDG17: PARTNERSHIP FOR THE GOALS (Mandatory for inclusion in overall Impact Rankings)
A3: 17.2 | B3: Relationships to support the goals
A4: 17.2.1 | B4: Relationships with regional NGOs and government for SDG policy Have direct involvement in, or input into, national government or regional non-government organisations SDG policy development - including identifying problems and challenges, developing policies and strategies, modelling likely futures with and without interventions, monitoring and reporting on interventions, and enabling adaptive management | C4: YES/NO | D4: YES | E4: NO
A5: 17.2.2 | B5: Cross sectoral dialogue about SDGs Initiate and participate in cross-sectoral dialogue about the SDGs, e.g. conferences involving government or NGOs | C5: YES/NO | D5: YES | E5: NO
A6: 17.2.3 | B6: International collaboration data gathering for SDG Participate in international collaboration on gathering or measuring data for the SDGs | C6: YES/NO | D6: YES | E6: NO
A7: 17.2.4 | B7: Collaboration for SDG best practice Through international collaboration and research, review comparative approaches and develop international best practice on tackling the SDGs | C7: YES/NO | D7: YES | E7: NO
A8: 17.2.5 | B8: Collaboration with NGOs for SDGs Collaborate with NGOs to tackle the SDGs through: student volunteering programmes, research programmes, or development of educational resources •student volunteering programmes •research programmes •development of educational resources | C8: Picklist | D8: YES | E8: NO
A9: 17.3 | B9: Publication of SDG reports
A10: 17.3.1 | B10: Publication of SDG reports - per SDG Publish progress against SDG1, either individually or within an annual report ●overall report ●separate report | C10: Picklist | D10: YES | E10: NO
A11: 17.3.2 | B11: Publication of SDG reports - per SDG Publish progress against SDG2, either individually or within an annual report ●overall report ●separate report
A12: 17.3.3 | B12: Publication of SDG reports - per SDG Publish progress against SDG3, either individually or within an annual report ●overall report ●separate report
A13: 17.3.4 | B13: Publication of SDG reports - per SDG Publish progress against SDG4, either individually or within an annual report ●overall report ●separate report
A14: 17.3.5 | B14: Publication of SDG reports - per SDG Publish progress against SDG5, either individually or within an annual report ●overall report ●separate report
A15: 17.3.6 | B15: Publication of SDG reports - per SDG Publish progress against SDG6, either individually or within an annual report ●overall report ●separate report
A16: 17.3.7 | B16: Publication of SDG reports - per SDG Publish progress against SDG7, either individually or within an annual report ●overall report ●separate report
A17: 17.3.8 | B17: Publication of SDG reports - per SDG Publish progress against SDG8, either individually or within an annual report ●overall report ●separate report
A18: 17.3.9 | B18: Publication of SDG reports - per SDG Publish progress against SDG9, either individually or within an annual report ●overall report ●separate report
A19: 17.3.10 | B19: Publication of SDG reports - per SDG Publish progress against SDG10, either individually or within an annual report ●overall report ●separate report
A20: 17.3.11 | B20: Publication of SDG reports - per SDG Publish progress against SDG11, either individually or within an annual report ●overall report ●separate report
A21: 17.3.12 | B21: Publication of SDG reports - per SDG Publish progress against SDG12, either individually or within an annual report ●overall report ●separate report
A22: 17.3.13 | B22: Publication of SDG reports - per SDG Publish progress against SDG13, either individually or within an annual report ●overall report ●separate report
... A26: 17.3.17 | B26: Publication of SDG reports - per SDG Publish progress against SDG17, either individually or within an annual report ●overall report ●separate report
A27: 17.4 | B27: Education for the SDGs
A28: 17.4.1 | B28: Education for SDGs commitment to meaningful education Have a commitment to meaningful education around the SDGs across the university, relevant and applicable to all students • Education integrated across full curriculum • Mandatory education for all •Optional education for all | C28: Picklist | D28: YES | E28: NO
A29: 17.4.2 | B29: Education for SDGs specific courses on sustainability Have dedicated courses (full degrees, or electives) that address sustainability and the SDGs. | C29: YES/NO | D29: YES | E29: NO
A30: 17.4.3 | B30: Education for SDGs in the wider community Have dedicated outreach educational activities for the wider community • Alumni • Local community •Displaced people and refugees | C30: Picklist | D30: YES | E30: NO
A31: 17.4.4 | B31: Sustainable Literacy This question explores how you evaluate your students’ ability to learn and retain key concepts of sustainability. For 2025 we will not score this question but will use it to inform our decisions for 2026. Measure the sustainability literacy of students. | C31: YES/NO | D31: YES | E31: NO
B33: SDG1: NO POVERTY
A34: 1.2 | B34: Proportion of students receiving financial aid to attend university because of poverty
A35: 1.2.1 | B35: Low income students receiving financial aid
B36: Number of students | C36: Continuous | D36: NO | E36: NO
B37: Number of low income students receiving financial aid
A38: 1.3 | B38: University anti-poverty programmes
A39: 1.3.1 | B39: Bottom financial quintile admission target Targets to admit students who fall into the bottom 20% of household income group (or a more tightly defined target) in the country. | C39: YES/NO | D39: YES | E39: NO
A40: 1.3.2 | B40: Bottom financial quintile student success Graduation/completion targets for students who fall into the bottom 20% of household income group (or a more tightly defined target) in the country. | C40: YES/NO | D40: YES | E40: NO
A41: 1.3.3 | B41: Low-income student support Provide support (e.g. food, housing, transportation, legal services) for students from low income families to enable them to complete university. •Free •Subsidised | C41: Picklist | D41: YES | E41: NO
A42: 1.3.4 | B42: Bottom financial quintile student support Programmes or initiatives to assist students who fall into the bottom 20% of household income group (or a more tightly defined target) in the country to successfully complete their studies. | C42: YES/NO | D42: YES | E42: NO
A43: 1.3.5 | B43: Low or lower-middle income countries student support Schemes to support poor students from low or lower-middle income countries (e.g. offering free education, grants). | C43: YES/NO | D43: YES | E43: NO
A44: 1.4 | B44: Community anti-poverty programmes
...

Sheet example
A1: Type | B1: Metric and indicator reference | C1: Metric / Indicator | D1: Value (for continuous data) | E1: Yes/No | F1: Evidence1 | G1: Public (Yes/No)
A2: Metric | B2: 1.2 | C2: Proportion of students receiving financial aid to attend university because of poverty
A3: Indicator | B3: 1.2.1 | C3: Students receiving financial aid
C4: Number of students | D4: 20458
C5: Number of low income students receiving financial aid | D5: 5326
A6: Metric | B6: 1.3 | C6: University anti-poverty programmes
A7: Indicator | B7: 1.3.1 | C7: Bottom financial quintile admission target Targets to admit students who fall into the bottom 20% of household income group (or a more tightly defined target) in the country. | E7: no
A8: Indicator | B8: 1.3.2 | C8: Bottom financial quintile student success Graduation/completion targets for students who fall into the bottom 20% of household income group (or a more tightly defined target) in the country. | E8: yes | F8: URL | G8: yes
A9: Indicator | B9: 1.3.3 | C9: Low-income student support Provide support (e.g. food, housing, transportation, legal services) for students from low income families to enable them to complete university. | E9: yes
C10: free | E10: no | F10: URL | G10: yes
C11: subsidised | E11: yes
A12: Indicator | B12: 1.3.4 | C12: Bottom financial quintile student support Programmes or initiatives to assist students who fall into the bottom 20% of household income group (or a more tightly defined target) in the country to successfully complete their studies. | E12: no
A13: Indicator | B13: 1.3.5 | C13: Low or lower-middle income countries student support Schemes to support poor students from low or lower-middle income countries (e.g. offering free education, grants). | E13: no
A14: Metric | B14: 1.4 | C14: Community anti-poverty programmes
A15: Indicator | B15: 1.4.1 | C15: Local start-up assistance Provide assistance in the local community supporting the start-up of sustainable businesses through relevant education or resources (e.g. mentorship programmes, training workshops, access to university facilities). | E15: yes
C16: free | E16: no | F16: URL | G16: yes
C17: paid | E17: yes
A18: Indicator | B18: 1.4.2 | C18: Local start-up financial assistance Provide financial assistance to the local community supporting the start-up of sustainable businesses. | E18: yes | F18: URL | G18: yes
A19: Indicator | B19: 1.4.3 | C19: Programmes for services access Organise training or programmes to improve access to basic services for all. | E19: yes
C20: directly | E20: yes | F20: pdf report | G20: yes
C21: indirectly | E21: no
A22: Indicator | B22: 1.4.4 | C22: Policy addressing poverty Participate in policy making at local, regional, national and/or global level to implement programmes and policies to end poverty in all its dimensions. | E22: yes
C23: local | E23: yes | F23: URL | G23: yes
C24: regional | E24: yes
C25: national | E25: no
C26: global | E26: yes

Sheet SDG1
A1: SDG1: No Poverty
A2: Type | B2: Metric and indicator reference | C2: Metric / Indicator | D2: Value (for continuous data) | E2: Yes/No | F2: Evidence1 | G2: Public (Yes/No)
A3: Metric | B3: 1.2 | C3: Proportion of students receiving financial aid to attend university because of poverty
A4: Indicator | B4: 1.2.1 | C4: Low income students receiving financial aid
C5: Number of students
C6: Number of low income students receiving financial aid
A7: Metric | B7: 1.3 | C7: University anti-poverty programmes
A8: Indicator | B8: 1.3.1 | C8: Bottom financial quintile admission target Targets to admit students who fall into the bottom 20% of household income group (or a more tightly defined target) in the country.
A9: Indicator | B9: 1.3.2 | C9: Bottom financial quintile student success Graduation/completion targets for students who fall into the bottom 20% of household income group (or a more tightly defined target) in the country.
A10: Indicator | B10: 1.3.3 | C10: Low-income student support Provide support (e.g. food, housing, transportation, legal services) for students from low income families to enable them to complete university.
C11: free
C12: subsidised
A13: Indicator | B13: 1.3.4 | C13: Bottom financial quintile student support Programmes or initiatives to assist students who fall into the bottom 20% of household income group (or a more tightly defined target) in the country to successfully complete their studies.
A14: Indicator | B14: 1.3.5 | C14: Low or lower-middle income countries student support Schemes to support poor students from low or lower-middle income countries (e.g. offering free education, grants).
A15: Metric | B15: 1.4 | C15: Community anti-poverty programmes
A16: Indicator | B16: 1.4.1 | C16: Local start-up assistance Provide assistance in the local community supporting the start-up of financially and socially sustainable businesses through relevant education or resources (e.g. mentorship programmes, training workshops, access to university facilities).
C17: free
C18: paid
A19: Indicator | B19: 1.4.2 | C19: Local start-up financial assistance Provide financial assistance to the local community supporting the start-up of financially and socially sustainable businesses.
A20: Indicator | B20: 1.4.3 | C20: Programmes for services access Organise training or programmes to improve access to basic services for all.
C21: directly
C22: indirectly
A23: Indicator | B23: 1.4.4 | C23: Policy addressing poverty Participate in policy making at local, regional, national and/or global level to implement programmes and policies to end poverty in all its dimensions.
C24: local
C25: regional
C26: national
C27: global

Sheet SDG2
A1: SDG2: Zero Hunger
A2: Type | B2: Metric and indicator reference | C2: Metric / Indicator | D2: Value (for continuous data) | E2: Yes/No | F2: Evidence1 | G2: Public (Yes/No)
A3: Metric | B3: 2.2 | C3: Campus food waste
A4: Indicator | B4: 2.2.1 | C4: Campus food waste tracking Measure the amount of food waste generated from food served within the university.
C5: whole university
C6: partial measurement
A7: Indicator | B7: 2.2.2 | C7: Campus food waste
C8: Total food waste
C9: Campus population
A10: Metric | B10: 2.3 | C10: Student hunger
A11: Indicator | B11: 2.3.1 | C11: Student food insecurity and hunger Have a programme in place on student food insecurity.
A12: Indicator | B12: 2.3.2 | C12: Students hunger interventions Provide interventions to prevent or alleviate hunger among students (e.g. including supply and access to food banks/pantries)._x000D_
A13: Indicator | B13: 2.3.3 | C13: Sustainable food choices on campus Provide sustainable food choices for all on campus, including vegetarian and vegan food.
C16: all food outlets
C17: selected food outlets
A18: Indicator | B18: 2.3.4 | C18: Healthy and affordable food choices Provide healthy and affordable food choices for all on campus.
C19: all food outlets
C20: selected food outlets
A21: Indicator | B21: 2.3.5 | C21: Staff hunger interventions Provide interventions to prevent or alleviate hunger among members of staff (e.g. including supply and access to food banks/pantries).
A22: Metric | B22: 2.4 | C22: Proportion of graduates in agriculture and aquaculture including sustainability aspects
A23: Indicator | B23: 2.4.1 | C23: Proportion of graduates in agriculture and aquaculture
C24: Number of graduates
C25: Number of graduates from agriculture and aquaculture courses including sustainability aspects
A26: Metric | B26: 2.5 | C26: National hunger
A27: Indicator | B27: 2.5.1 | C27: Access to food security knowledge Provide access on food security and sustainable agriculture and aquaculture knowledge, skills or technology to local farmers and food producers.
C30: free
C31: paid
A32: Indicator | B32: 2.5.2 | C32: Events for local farmers and food producers Provide events for local farmers and food producers to connect and transfer knowledge
C35: free
C36: paid
A37: Indicator | B37: 2.5.3 | C37: University access to local farmers and food producers Provide access to university facilities (e.g. labs, technology, plant stocks) to local farmers and food producers to improve sustainable farming practices.
C40: free
C41: paid
A42: Indicator | B42: 2.5.4 | C42: Sustainable food purchases Prioritise purchase of products from local, sustainable sources.

Sheet SDG3
A1: SDG3: Good Health and Well-being
A2: Type | B2: Metric and indicator reference | C2: Metric / Indicator | D2: Metrica / Indicado Este año solicitamos información del año académico 2024. | E2: Fuente datos UDES | F2: Value (for continuous data) | G2: Yes/No | H2: Evidence1 | I2: Public (Yes/No) | J2: Comentarios" con una longitud máxima de 1000 caracteres
A3: Metric | B3: 3.2 | C3: Number graduating in health professions | D3: Número de graduados en profesiones de la salud | E3: Analitica
A4: Indicator | B4: 3.2.1 | C4: Proportion of graduates in health professions | D4: Proporción de graduados en profesiones de la salud
C5: Number of graduates | D5: Número de graduados
C6: Number of graduates in health professions | D6: Número de graduados en profesiones de la salud
A7: Metric | B7: 3.3 | C7: Collaborations and health services | D7: Colaboraciones y servicios sanitarios | E7: Convenios V Extensión Masira - PURE red de aliandos (DRNI)
A8: Indicator | B8: 3.3.1 | C8: Current collaborations with health institutions Have current collaborations with local, national, or global health institutions to improve health and well-being outcomes. | D8: Colaboraciones actuales con instituciones de salud Tener colaboraciones actuales con instituciones de salud locales, nacionales o globales para mejorar los resultados de salud y bienestar.
C9: local collaboration | D9: Colaboración local
C10: national collaboration | D10: colaboración nacional
C11: global cooperation | D11: Cooperación global
A12: Indicator | B12: 3.3.2 | C12: Health outreach programmes Deliver outreach programmes and projects in the local community (which can include student volunteering programmes) to improve or promote health and well-being including hygiene, nutrition, family planning, sports, exercise, aging well, and other health and well-being related topics. This can also include outreach programmes to displaced or refugee communities local to the institution. | D12: Programas de extensión sanitaria Ofrecer programas y proyectos de divulgación en la comunidad local (que pueden incluir programas de voluntariado estudiantil) para mejorar o promover la salud y el bienestar, incluida la higiene, la nutrición, la planificación familiar, los deportes, el ejercicio, el envejecimiento saludable y otros temas relacionados con la salud y el bienestar. Esto también puede incluir programas de divulgación para las comunidades desplazadas o refugiadas locales de la institución. | E12: VE = Educon Bienestar Institucional
C13: Local communities | D13: Comunidades locales
C14: Disadvantaged people | D14: Personas desfavorecidas
C15: Refugee/immigrant communities | D15: Comunidades de refugiados/inmigrantes
A16: Indicator | B16: 3.3.3 | C16: Shared sports facilities Share sports facilities with the local community, for instance with local schools or with the general public. | D16: Instalaciones deportivas compartidas Compartir instalaciones deportivas con la comunidad local, por ejemplo, con las escuelas locales o con el público en general. | E16: Planta física Bienestar
C17: Free access to all facilities | D17: Acceso gratuito a todas las instalaciones
C18: Free access to some facilities | D18: Acceso gratuito a algunas instalaciones
C19: Charged access | D19: Acceso de pago
A20: Indicator | B20: 3.3.4 | C20: Sexual and reproductive health care services for students Provide students access to sexual and reproductive health-care services including information and education services. | D20: Servicios de atención de salud sexual y reproductiva para estudiantes Proporcionar a los estudiantes acceso a servicios de atención de salud sexual y reproductiva, incluidos servicios de información y educación. | E20: Bienestar institucional Neurotrauma
C21: Free access | D21: Acceso gratuito
C22: Charged access | D22: Acceso de pago
A23: Indicator | B23: 3.3.5 | C23: Mental health support for students Provide students with access to mental health support. | D23: Apoyo a la salud mental para estudiantes Proporcionar a los estudiantes acceso a apoyo de salud mental. | E23: Bienestar institucional Neurotrauma Programa de Psicología
C24: Active promotion of good mental health | D24: Promoción activa de una buena salud mental
C25: Access to (or signposting to) free mental health support | D25: Acceso a (o señalización de) apoyo gratuito de salud mental
C26: Access to (or signposting to) charged mental health support | D26: Acceso (o señalización de) apoyo de salud mental de pago
A27: Indicator | B27: 3.3.6 | C27: Smoke-free policy Have a ‘smoke-free’ policy. | D27: Política libre de humo Tenga una política "libre de humo". | E27: Bienestar institucional Udes verde
C28: Smoking-free campus | D28: Campus libre de humo
C29: Smoking in designated areas | D29: Fumar en áreas designadas
A30: Indicator | B30: 3.3.7 | C30: Mental health support for staff Provide staff with access to mental health support. | D30: Apoyo de salud mental para el personal Proporcionar al personal acceso a apoyo de salud mental. | E30: Bienestar institucional Neurotrauma Programa de Psicología
C31: Active promotion of good mental health | D31: Promoción activa de una buena salud mental
C32: Access to (or signposting to) free mental health support | D32: Acceso a (o señalización de) apoyo gratuito de salud mental
C33: Access to (or signposting to) charged mental health support | D33: Acceso (o señalización de) apoyo de salud mental de pago

Sheet SDG4
A1: SDG4: Quality Education | K1: Gestión interna UDES 2026
A2: Type | B2: Metric and indicator reference | C2: Metric / Indicator | D2: Metrica / Indicador Este año solicitamos información del año académico 2024. | E2: Fuente datos | F2: Value (for continuous data) | G2: Yes/No | H2: Evidence1 | I2: Public (Yes/No) | J2: Comentarios" con una longitud máxima de 1000 caracteres | K2: Coordinación del reporte | L2: Responsable / fuente principal | M2: Dependencia(s) de apoyo | N2: Tipo de requerimiento | O2: Peso oficial THE | P2: Prioridad | Q2: Estado
A3: Metric | B3: 4.2 | C3: Proportion of graduates with teaching qualification | D3: Proporción de titulados con titulación docente | E3: Planeación Institucional | K3: Planeación Institucional | L3: Planeación Institucional | M3: Registro y Control Académico / Vicerrectoría de Enseñanza | N3: Métrica / bloque de evaluación | O3: 0.154 | P3: =IF(ISBLANK(O3),"",IF(O3=0,"Baja",IF(OR(O3>=10%,ISNUMBER(SEARCH("Política",N3))),"Alta","Media"))) -> Alta | Q3: Pendiente
A4: Indicator | B4: 4.2.1 | C4: Proportion of graduates with relevant qualification for teaching | D4: Proporción de titulados con cualificación pertinente para la docencia | K4: Planeación Institucional | L4: Planeación Institucional | M4: Registro y Control Académico / Vicerrectoría de Enseñanza | N4: Dato cuantitativo 2024 | O4: 0.154 | P4: =IF(ISBLANK(O4),"",IF(O4=0,"Baja",IF(OR(O4>=10%,ISNUMBER(SEARCH("Política",N4))),"Alta","Media"))) -> Alta | Q4: Pendiente
C5: Number of graduates | D5: Número de graduados | K5: Planeación Institucional | L5: Planeación Institucional | M5: Registro y Control Académico / Vicerrectoría de Enseñanza | N5: Dato cuantitativo 2024
C6: Number of graduates who gained a qualification that entitled them to teach at primary school level | D6: Número de titulados que han obtenido un título que les da derecho a la enseñanza primaria | K6: Planeación Institucional | L6: Planeación Institucional | M6: Registro y Control Académico / Vicerrectoría de Enseñanza | N6: Dato cuantitativo 2024
A7: Metric | B7: 4.3 | C7: Lifelong learning measures | D7: Medidas de aprendizaje permanente | E7: EDUCON Campus Virtual UDES Biblioteca | K7: Planeación Institucional | L7: EDUCON | M7: Campus Virtual UDES / Biblioteca | N7: Métrica / bloque de evaluación | O7: 0.268 | P7: =IF(ISBLANK(O7),"",IF(O7=0,"Baja",IF(OR(O7>=10%,ISNUMBER(SEARCH("Política",N7))),"Alta","Media"))) -> Alta | Q7: Pendiente
A8: Indicator | B8: 4.3.1 | C8: Public resources (lifelong learning) Provide free access to educational resources for those not studying at the university. | D8: Recursos públicos (aprendizaje permanente) Proporcionar acceso gratuito a recursos educativos para aquellos que no estudian en la universidad. | K8: Planeación Institucional | L8: EDUCON | M8: Campus Virtual UDES / Biblioteca | N8: Evidencia pública | O8: 0.05 | P8: =IF(ISBLANK(O8),"",IF(O8=0,"Baja",IF(OR(O8>=10%,ISNUMBER(SEARCH("Política",N8))),"Alta","Media"))) -> Media | Q8: Pendiente
C9: Free courses leading to certificate or award | D9: Cursos gratuitos que conducen a certificados o premios | K9: Planeación Institucional | L9: EDUCON | M9: Campus Virtual UDES / Biblioteca | N9: Evidencia pública
C10: Free access to campus facilities and equipment | D10: Acceso gratuito a las instalaciones y equipos del campus | K10: Planeación Institucional | L10: EDUCON | M10: Campus Virtual UDES / Biblioteca | N10: Evidencia pública
C11: Free access to online resources | D11: Acceso gratuito a recursos en línea | K11: Planeación Institucional | L11: EDUCON | M11: Campus Virtual UDES / Biblioteca | N11: Evidencia pública
A12: Indicator | B12: 4.3.2 | C12: Public events (lifelong learning) Host educational events at university that are open to the general public. | D12: Eventos públicos (aprendizaje permanente) Organice eventos educativos en la universidad que estén abiertos al público en general. | E12: EDUCON / Graduados Comunicaciones Biblioteca Programas Campus Virtual UDES Talento Humano | K12: Planeación Institucional | L12: EDUCON / Graduados | M12: Comunicaciones / Biblioteca / Programas / Campus Virtual UDES / Talento Humano | N12: Evidencia pública | O12: 0.05 | P12: =IF(ISBLANK(O12),"",IF(O12=0,"Baja",IF(OR(O12>=10%,ISNUMBER(SEARCH("Política",N12))),"Alta","Media"))) -> Media | Q12: Pendiente
C13: Free events | D13: Eventos gratuitos | K13: Planeación Institucional | L13: EDUCON / Graduados | M13: Comunicaciones / Biblioteca / Programas / Campus Virtual UDES / Talento Humano | N13: Evidencia pública
C14: Both changed and free | D14: Cambiado y libre | K14: Planeación Institucional | L14: EDUCON / Graduados | M14: Comunicaciones / Biblioteca / Programas / Campus Virtual UDES / Talento Humano | N14: Evidencia pública
A15: Indicator | B15: 4.3.3 | C15: Vocational training events (lifelong learning) Host events at university that are open to the general public: executive education programmes (this refers to short courses for people who are not attending the university; this specifically excludes courses like MBA) and/or vocational training. | D15: Eventos de formación profesional (aprendizaje permanente) Organizar eventos en la universidad abiertos al público en general: programas de educación ejecutiva (esto se refiere a cursos cortos para personas que no asisten a la universidad; esto excluye específicamente cursos como MBA) y/o formación profesional. | E15: EDUCON / Graduados Desarrollo Profesoral Comunicaciones Biblioteca Programas Campus Virtual UDES Talento Humano | K15: Planeación Institucional | L15: EDUCON / Graduados | M15: Desarrollo Profesoral / Comunicaciones / Biblioteca / Programas / Campus Virtual UDES / Talento Humano | N15: Evidencia pública | O15: 0.05 | P15: =IF(ISBLANK(O15),"",IF(O15=0,"Baja",IF(OR(O15>=10%,ISNUMBER(SEARCH("Política",N15))),"Alta","Media"))) -> Media | Q15: Pendiente
C16: Ad hoc | D16: Ad hoc | K16: Planeación Institucional | L16: EDUCON / Graduados | M16: Desarrollo Profesoral / Comunicaciones / Biblioteca / Programas / Campus Virtual UDES / Talento Humano | N16: Evidencia pública
C17: On programmed basis | D17: De forma programada | K17: Planeación Institucional | L17: EDUCON / Graduados | M17: Desarrollo Profesoral / Comunicaciones / Biblioteca / Programas / Campus Virtual UDES / Talento Humano | N17: Evidencia pública
A18: Indicator | B18: 4.3.4 | C18: Education outreach activities beyond campus Undertake educational outreach activities (e.g. tailored lectures or demonstrations) beyond campus – in local schools, in the community. This can include voluntary student-run schemes. | D18: Actividades de divulgación educativa más allá del campus Emprender actividades de divulgación educativa (por ejemplo, conferencias o demostraciones personalizadas) más allá del campus, en las escuelas locales, en la comunidad. Esto puede incluir esquemas voluntarios dirigidos por estudiantes. | E18: EDUCON / Graduados Desarrollo Profesoral Comunicaciones Biblioteca Programas Campus Virtual UDES Talento Humano | K18: Planeación Institucional | L18: EDUCON / Graduados | M18: Desarrollo Profesoral / Comunicaciones / Biblioteca / Programas / Campus Virtual UDES / Talento Humano | N18: Evidencia pública | O18: 0.05 | P18: =IF(ISBLANK(O18),"",IF(O18=0,"Baja",IF(OR(O18>=10%,ISNUMBER(SEARCH("Política",N18))),"Alta","Media"))) -> Media | Q18: Pendiente
C19: Ad hoc | D19: Ad hoc | K19: Planeación Institucional | L19: EDUCON / Graduados | M19: Desarrollo Profesoral / Comunicaciones / Biblioteca / Programas / Campus Virtual UDES / Talento Humano | N19: Evidencia pública
C20: On programmed basis | D20: De forma programada | K20: Planeación Institucional | L20: EDUCON / Graduados | M20: Desarrollo Profesoral / Comunicaciones / Biblioteca / Programas / Campus Virtual UDES / Talento Humano | N20: Evidencia pública
A21: Indicator | B21: 4.3.5 | C21: Lifelong learning access policy A policy that ensures that access to these activities is accessible to all, regardless of ethnicity, religion, disability immigration status or gender. | D21: Política de acceso al aprendizaje permanente Una política que garantice que el acceso a estas actividades sea accesible para todos, independientemente de su origen étnico, religión, discapacidad, estado migratorio o género. | E21: Vicerrectoría de Enseñanza Vicerrectoría de Extensión | K21: Planeación Institucional | L21: Vicerrectoría de Enseñanza | M21: Vicerrectoría de Extensión | N21: Política / evidencia pública | O21: 0.068 | P21: =IF(ISBLANK(O21),"",IF(O21=0,"Baja",IF(OR(O21>=10%,ISNUMBER(SEARCH("Política",N21))),"Alta","Media"))) -> Alta | Q21: Pendiente
A22: Metric | B22: 4.4 | C22: Proportion of first-generation students | D22: Proporción de estudiantes de primera generación | E22: Planeación Institucional | K22: Planeación Institucional | L22: Planeación Institucional | M22: Registro y Control Académico | N22: Métrica / bloque de evaluación | O22: 0.308 | P22: =IF(ISBLANK(O22),"",IF(O22=0,"Baja",IF(OR(O22>=10%,ISNUMBER(SEARCH("Política",N22))),"Alta","Media"))) -> Alta | Q22: Pendiente
A23: Indicator | B23: 4.4.1 | C23: Proportion of first-generation students | D23: Proporción de estudiantes de primera generación | K23: Planeación Institucional | L23: Planeación Institucional | M23: Registro y Control Académico | N23: Dato cuantitativo 2024 | O23: 0.308 | P23: =IF(ISBLANK(O23),"",IF(O23=0,"Baja",IF(OR(O23>=10%,ISNUMBER(SEARCH("Política",N23))),"Alta","Media"))) -> Alta | Q23: Pendiente
C24: Number of students starting a degree | D24: Número de estudiantes que inician una carrera | K24: Planeación Institucional | L24: Planeación Institucional | M24: Registro y Control Académico | N24: Dato cuantitativo 2024
C25: Number of first-generation students starting a degree | D25: Número de estudiantes de primera generación que comienzan una carrera | K25: Planeación Institucional | L25: Planeación Institucional | M25: Registro y Control Académico | N25: Dato cuantitativo 2024

Sheet SDG5
A1: SDG5: Gender Equality | K1: Gestión interna UDES 2026
A2: Type | B2: Metric and indicator reference | C2: Metric / Indicator | D2: Métrica / Indicador Este año solicitamos información del año académico 2024. | E2: Fuente datos | F2: Value (for continuous data) | G2: Yes/No | H2: Evidence1 | I2: Public (Yes/No) | J2: Comentarios" con una longitud máxima de 1000 caracteres | K2: Coordinación del reporte | L2: Responsable / fuente principal | M2: Dependencia(s) de apoyo | N2: Tipo de requerimiento | O2: Peso oficial THE | P2: Prioridad | Q2: Estado
A3: Metric | B3: 5.2 | C3: Proportion of first-generation female students | D3: Proporción de alumnas de primera generación | E3: Planeación Institucional | K3: Planeación Institucional | L3: Planeación Institucional | M3: Registro y Control Académico | N3: Métrica / bloque de evaluación | O3: 0.154 | P3: =IF(ISBLANK(O3),"",IF(O3=0,"Baja",IF(OR(O3>=10%,ISNUMBER(SEARCH("Política",N3))),"Alta","Media"))) -> Alta | Q3: Pendiente
A4: Indicator | B4: 5.2.1 | C4: Proportion of women first-generation | D4: Proporción de mujeres de primera generación | K4: Planeación Institucional | L4: Planeación Institucional | M4: Registro y Control Académico | N4: Dato cuantitativo 2024 | O4: 0.154 | P4: =IF(ISBLANK(O4),"",IF(O4=0,"Baja",IF(OR(O4>=10%,ISNUMBER(SEARCH("Política",N4))),"Alta","Media"))) -> Alta | Q4: Pendiente
C5: Number of women starting a degree | D5: Número de mujeres que comienzan una carrera | K5: Planeación Institucional | L5: Planeación Institucional | M5: Registro y Control Académico | N5: Dato cuantitativo 2024
C6: Number of first-generation women starting a degree | D6: Número de mujeres de primera generación que comienzan una carrera | K6: Planeación Institucional | L6: Planeación Institucional | M6: Registro y Control Académico | N6: Dato cuantitativo 2024
A7: Metric | B7: 5.3 | C7: Student access measures | D7: Medidas de acceso de los estudiantes | E7: Planeación Institucional | K7: Planeación Institucional | L7: Planeación Institucional | M7: Vicerrectoría de Enseñanza / Registro y Control Académico | N7: Métrica / bloque de evaluación | O7: 0.154 | P7: =IF(ISBLANK(O7),"",IF(O7=0,"Baja",IF(OR(O7>=10%,ISNUMBER(SEARCH("Política",N7))),"Alta","Media"))) -> Alta | Q7: Pendiente
A8: Indicator | B8: 5.3.1 | C8: Tracking access measures Systematically measure and track women’s application rate, acceptance or entry rate. | D8: Seguimiento de las medidas de acceso Medir y rastrear sistemáticamente la tasa de solicitud, aceptación o entrada de las mujeres. | K8: Planeación Institucional | L8: Planeación Institucional | M8: Vicerrectoría de Enseñanza / Registro y Control Académico | N8: Evidencia pública | O8: 0.016 | P8: =IF(ISBLANK(O8),"",IF(O8=0,"Baja",IF(OR(O8>=10%,ISNUMBER(SEARCH("Política",N8))),"Alta","Media"))) -> Media | Q8: Pendiente
A9: Indicator | B9: 5.3.2 | C9: Policy for women applications and entry Have a policy (e.g. an Access and Participation plan) addressing women’s applications, acceptance, entry, and participation at the university. | D9: Política para las solicitudes y la entrada de mujeres Tener una política (por ejemplo, un plan de acceso y participación) que aborde las solicitudes, la aceptación, el ingreso y la participación de las mujeres en la universidad. | E9: Vicerrectoría de Enseñanza Planeación Institucional | K9: Planeación Institucional | L9: Planeación Institucional | M9: Vicerrectoría de Enseñanza | N9: Política / evidencia pública | O9: 0.046 | P9: =IF(ISBLANK(O9),"",IF(O9=0,"Baja",IF(OR(O9>=10%,ISNUMBER(SEARCH("Política",N9))),"Alta","Media"))) -> Alta | Q9: Pendiente
A10: Indicator | B10: 5.3.3 | C10: Women’s access schemes Provide women’s access schemes, including mentoring, scholarships, or other provision | D10: Planes de acceso de las mujeres Proporcionar esquemas de acceso para mujeres, incluida tutoría, becas u otras disposiciones | E10: Vicerrectoría de Enseñanza Vicerrectoría de Investigaciones (Orquidea de la ciencia, otras mujeres), Conv Minciencias Planeación Institucional Credito y Cartera DRNI | K10: Planeación Institucional | L10: Planeación Institucional | M10: Vicerrectoría de Enseñanza / Vicerrectoría de Investigaciones (Orquidea de la ciencia, otras mujeres), Conv Minciencias / Credito y Cartera / DRNI | N10: Evidencia pública | O10: 0.046 | P10: =IF(ISBLANK(O10),"",IF(O10=0,"Baja",IF(OR(O10>=10%,ISNUMBER(SEARCH("Política",N10))),"Alta","Media"))) -> Media | Q10: Pendiente
C11: Mentoring | D11: Tutoría | K11: Planeación Institucional | L11: Planeación Institucional | M11: Vicerrectoría de Enseñanza / Vicerrectoría de Investigaciones (Orquidea de la ciencia, otras mujeres), Conv Minciencias / Credito y Cartera / DRNI | N11: Evidencia pública
C12: Scholarship | D12: Beca | K12: Planeación Institucional | L12: Planeación Institucional | M12: Vicerrectoría de Enseñanza / Vicerrectoría de Investigaciones (Orquidea de la ciencia, otras mujeres), Conv Minciencias / Credito y Cartera / DRNI | N12: Evidencia pública
C13: Other provision | D13: Otras disposiciones | K13: Planeación Institucional | L13: Planeación Institucional | M13: Vicerrectoría de Enseñanza / Vicerrectoría de Investigaciones (Orquidea de la ciencia, otras mujeres), Conv Minciencias / Credito y Cartera / DRNI | N13: Evidencia pública
A14: Indicator | B14: 5.3.4 | C14: Women’s application in underrepresented subjects Encourage applications by women in subjects where they are underrepresented. Through university outreach or through collaboration with other universities, community groups, government or NGOs in regional or national campaigns. | D14: Solicitud de las mujeres en materias subrepresentadas Fomentar las solicitudes de mujeres en materias en las que están subrepresentadas. A través de la extensión universitaria o mediante la colaboración con otras universidades, grupos comunitarios, gobiernos u ONG en campañas regionales o nacionales. | E14: Vicerrectoría de Extensión Vicerrectoría de Enseñanza Vicerrectoría de Investigaciones (Orquidea de la ciencia, otras mujeres), Conv Minciencias Planeación Institucional Credito y Cartera DRNI Mujer y Hogar / Miudes | K14: Planeación Institucional | L14: Planeación Institucional | M14: Vicerrectoría de Extensión / Vicerrectoría de Enseñanza / Vicerrectoría de Investigaciones (Orquidea de la ciencia, otras mujeres), Conv Minciencias / Credito y Cartera / DRNI / Mujer y Hogar / Miudes | N14: Evidencia pública | O14: 0.046 | P14: =IF(ISBLANK(O14),"",IF(O14=0,"Baja",IF(OR(O14>=10%,ISNUMBER(SEARCH("Política",N14))),"Alta","Media"))) -> Media | Q14: Pendiente
C15: through university outreach | D15: a través de la extensión universitaria | K15: Planeación Institucional | L15: Planeación Institucional | M15: Vicerrectoría de Extensión / Vicerrectoría de Enseñanza / Vicerrectoría de Investigaciones (Orquidea de la ciencia, otras mujeres), Conv Minciencias / Credito y Cartera / DRNI / Mujer y Hogar / Miudes | N15: Evidencia pública
C16: through collaboration with other universities and/or community groups and/or government and/or NGOs in regional or national campaigns | D16: a través de la colaboración con otras universidades y/o grupos comunitarios y/o el gobierno y/o las ONG en campañas regionales o nacionales | K16: Planeación Institucional | L16: Planeación Institucional | M16: Vicerrectoría de Extensión / Vicerrectoría de Enseñanza / Vicerrectoría de Investigaciones (Orquidea de la ciencia, otras mujeres), Conv Minciencias / Credito y Cartera / DRNI / Mujer y Hogar / Miudes | N16: Evidencia pública
A17: Metric | B17: 5.4 | C17: Proportion of senior female academics | D17: Proporción de mujeres académicas de alto nivel | E17: Planeación Institucional | K17: Planeación Institucional | L17: Planeación Institucional | M17: Talento Humano | N17: Métrica / bloque de evaluación | O17: 0.154 | P17: =IF(ISBLANK(O17),"",IF(O17=0,"Baja",IF(OR(O17>=10%,ISNUMBER(SEARCH("Política",N17))),"Alta","Media"))) -> Alta | Q17: Pendiente
A18: Indicator | B18: 5.4.1 | C18: Proportion of senior female academics | D18: Proporción de mujeres académicas de alto nivel | K18: Planeación Institucional | L18: Planeación Institucional | M18: Talento Humano | N18: Dato cuantitativo 2024 | O18: 0.154 | P18: =IF(ISBLANK(O18),"",IF(O18=0,"Baja",IF(OR(O18>=10%,ISNUMBER(SEARCH("Política",N18))),"Alta","Media"))) -> Alta | Q18: Pendiente
C19: Number of senior academic staff | D19: Número de personal académico superior | K19: Planeación Institucional | L19: Planeación Institucional | M19: Talento Humano | N19: Dato cuantitativo 2024
C20: Number of female senior academic staff | D20: Número de mujeres en el personal académico superior | K20: Planeación Institucional | L20: Planeación Institucional | M20: Talento Humano | N20: Dato cuantitativo 2024
A21: Metric | B21: 5.5 | C21: Proportion of women receiving degrees | D21: Proporción de mujeres que reciben títulos | E21: Planeación Institucional | K21: Planeación Institucional | L21: Planeación Institucional | M21: Registro y Control Académico | N21: Métrica / bloque de evaluación | O21: 0.115 | P21: =IF(ISBLANK(O21),"",IF(O21=0,"Baja",IF(OR(O21>=10%,ISNUMBER(SEARCH("Política",N21))),"Alta","Media"))) -> Alta | Q21: Pendiente
A22: Indicator | B22: 5.5.1 | C22: Proportion of female degrees awarded | D22: Proporción de títulos femeninos otorgados | K22: Planeación Institucional | L22: Planeación Institucional | M22: Registro y Control Académico | N22: Dato cuantitativo 2024 | O22: 0.115 | P22: =IF(ISBLANK(O22),"",IF(O22=0,"Baja",IF(OR(O22>=10%,ISNUMBER(SEARCH("Política",N22))),"Alta","Media"))) -> Alta | Q22: Pendiente
C23: Number of graduates: Total | D23: Número de graduados: Total | K23: Planeación Institucional | L23: Planeación Institucional | M23: Registro y Control Académico | N23: Dato cuantitativo 2024
C24: Number of graduates by subject area (STEM, Medicine, Arts & Humanities / Social Sciences): Total | D24: Número de graduados por área temática (STEM, Medicina, Artes y Humanidades / Ciencias Sociales): Total | K24: Planeación Institucional | L24: Planeación Institucional | M24: Registro y Control Académico | N24: Dato cuantitativo 2024
C25: Number of graduates: STEM | D25: Número de graduados: STEM | K25: Planeación Institucional | L25: Planeación Institucional | M25: Registro y Control Académico | N25: Dato cuantitativo 2024
C26: Number of graduates: Medicine | D26: Número de graduados: Medicina | K26: Planeación Institucional | L26: Planeación Institucional | M26: Registro y Control Académico | N26: Dato cuantitativo 2024
C27: Number of graduates: Arts & Humanities / Social Sciences | D27: Número de graduados: Artes y Humanidades / Ciencias Sociales | K27: Planeación Institucional | L27: Planeación Institucional | M27: Registro y Control Académico | N27: Dato cuantitativo 2024
C28: Number of female graduates by subject area (STEM, Medicine, Arts & Humanities / Social Sciences): Total | D28: Número de mujeres graduadas por área temática (STEM, Medicina, Artes y Humanidades / Ciencias Sociales): Total | K28: Planeación Institucional | L28: Planeación Institucional | M28: Registro y Control Académico | N28: Dato cuantitativo 2024
C29: Number of female graduates: STEM | D29: Número de mujeres graduadas: STEM | K29: Planeación Institucional | L29: Planeación Institucional | M29: Registro y Control Académico | N29: Dato cuantitativo 2024
C30: Number of female graduates: Medicine | D30: Número de mujeres graduadas: Medicina | K30: Planeación Institucional | L30: Planeación Institucional | M30: Registro y Control Académico | N30: Dato cuantitativo 2024
C31: Number of female graduates: Arts & Humanities / Social Sciences | D31: Número de mujeres graduadas: Artes y Humanidades / Ciencias Sociales | K31: Planeación Institucional | L31: Planeación Institucional | M31: Registro y Control Académico | N31: Dato cuantitativo 2024
A32: Metric | B32: 5.6 | C32: Women’s progress measures | D32: Medidas de progreso de las mujeres | K32: Planeación Institucional | N32: Métrica / bloque de evaluación | O32: 0.153 | P32: =IF(ISBLANK(O32),"",IF(O32=0,"Baja",IF(OR(O32>=10%,ISNUMBER(SEARCH("Política",N32))),"Alta","Media"))) -> Alta | Q32: Pendiente
A33: Indicator | B33: 5.6.1 | C33: Policy of non-discrimination against women Have a policy of non-discrimination against women | D33: Política de no discriminación contra la mujer Tener una política de no discriminación contra las mujeres | E33: Vicerrectoría de Enseñanza Talento Humano | K33: Planeación Institucional | L33: Vicerrectoría de Enseñanza | M33: Talento Humano | N33: Política / evidencia pública | O33: 0.0195 | P33: =IF(ISBLANK(O33),"",IF(O33=0,"Baja",IF(OR(O33>=10%,ISNUMBER(SEARCH("Política",N33))),"Alta","Media"))) -> Alta | Q33: Pendiente
A34: Indicator | B34: 5.6.2 | C34: Non-discrimination policies for transgender Have a policy of non-discrimination for transgender people. | D34: Políticas de no discriminación para las personas transgénero Tener una política de no discriminación para las personas transgénero. | E34: Vicerrectoría de Enseñanza Talento Humano | K34: Planeación Institucional | L34: Vicerrectoría de Enseñanza | M34: Talento Humano | N34: Política / evidencia pública | O34: 0.0195 | P34: =IF(ISBLANK(O34),"",IF(O34=0,"Baja",IF(OR(O34>=10%,ISNUMBER(SEARCH("Política",N34))),"Alta","Media"))) -> Alta | Q34: Pendiente
A35: Indicator | B35: 5.6.3 | C35: Maternity policy Have a maternity policy that support women’s participation. | D35: Política de maternidad Tener una política de maternidad que apoye la participación de las mujeres. | E35: Vicerrectoría de Enseñanza Talento Humano | K35: Planeación Institucional | L35: Vicerrectoría de Enseñanza | M35: Talento Humano | N35: Política / evidencia pública | O35: 0.0095 | P35: =IF(ISBLANK(O35),"",IF(O35=0,"Baja",IF(OR(O35>=10%,ISNUMBER(SEARCH("Política",N35))),"Alta","Media"))) -> Alta | Q35: Pendiente
A36: Indicator | B36: 5.6.4 | C36: Childcare facilities for students Have accessible childcare facilities for students which allow recent mothers to attend university courses. | D36: Guarderías para estudiantes Tener guarderías accesibles para estudiantes que permitan a las madres recién nacidas asistir a la universidad Cursos. | E36: Vicerrectoría de Enseñanza Talento Humano Bienestar | K36: Planeación Institucional | L36: Vicerrectoría de Enseñanza | M36: Talento Humano / Bienestar | N36: Evidencia pública | O36: 0.019 | P36: =IF(ISBLANK(O36),"",IF(O36=0,"Baja",IF(OR(O36>=10%,ISNUMBER(SEARCH("Política",N36))),"Alta","Media"))) -> Media | Q36: Pendiente
C37: Free | D37: Gratis | K37: Planeación Institucional | L37: Vicerrectoría de Enseñanza | M37: Talento Humano / Bienestar | N37: Evidencia pública
C38: Paid | D38: Pagado | K38: Planeación Institucional | L38: Vicerrectoría de Enseñanza | M38: Talento Humano / Bienestar | N38: Evidencia pública
A39: Indicator | B39: 5.6.5 | C39: Childcare facilities for staff and faculty Have childcare facilities for staff and faculty | D39: Instalaciones de cuidado infantil para el personal y la facultad Tener instalaciones de cuidado infantil para el personal y la facultad. | E39: Vicerrectoría de Enseñanza Talento Humano Bienestar | K39: Planeación Institucional | L39: Vicerrectoría de Enseñanza | M39: Talento Humano / Bienestar | N39: Evidencia pública | O39: 0.019 | P39: =IF(ISBLANK(O39),"",IF(O39=0,"Baja",IF(OR(O39>=10%,ISNUMBER(SEARCH("Política",N39))),"Alta","Media"))) -> Media | Q39: Pendiente
C40: Free | D40: Gratis | K40: Planeación Institucional | L40: Vicerrectoría de Enseñanza | M40: Talento Humano / Bienestar | N40: Evidencia pública
...

Sheet SDG6
A1: SDG6: Clean Water and Sanitation
A2: Type | B2: Metric and indicator reference | C2: Metric / Indicator | D2: Value (for continuous data) | E2: Yes/No | F2: Evidence1 | G2: Public (Yes/No)
A3: Metric | B3: 6.2 | C3: Water consumption per person
A4: Indicator | B4: 6.2.1 | C4: Measure the total volume of water used in the university that is taken from mains supply, desalinated, or extracted from rivers, lakes, or aquifers?
C5: Whole university
C6: Partial measurement
A7: Indicator | B7: 6.2.2 | C7: Water consumption per person
C8: Volume of water used in the university: Inbound (treated/extracted water)
C9: Campus population
A10: Metric | B10: 6.3 | C10: Water usage and care
A11: Indicator | B11: 6.3.1 | C11: Wastewater treatment A process in place to treat wastewater.
A12: Indicator | B12: 6.3.2 | C12: Preventing water system pollution Processes to prevent polluted water entering the water system, including pollution caused by accidents and incidents at the university.
A13: Indicator | B13: 6.3.3 | C13: Free drinking water provided Provide free drinking water for students, staff and/or visitors (e.g. drinking water fountains).
A14: Indicator | B14: 6.3.4 | C14: Water-conscious building standards Apply building standards to minimise water use
A15: Indicator | B15: 6.3.5 | C15: Water-conscious planting Plant landscapes to minimise water usage. (e.g. use drought-tolerant plants)
A16: Metric | B16: 6.4 | C16: Water reuse
A17: Indicator | B17: 6.4.1 | C17: Water reuse policy Have a policy to maximise water reuse across the university?
A18: Indicator | B18: 6.4.2 | C18: Water reuse measurement Measure the reuse of water across the university?
A19: Metric | B19: 6.5 | C19: Water in the community
A20: Indicator | B20: 6.5.1 | C20: Water management educational opportunities Provide educational opportunities for local communities to learn about good water management
C21: Free
C22: Paid
A23: Indicator | B23: 6.5.2 | C23: Off-campus water conservation support Support practical water conservation off campus
A24: Indicator | B24: 6.5.3 | C24: Sustainable water extraction on campus Where water is extracted (for example from aquifers, lakes or rivers) utilise sustainable water extraction technologies on associated university grounds on and off campus.
A25: Indicator | B25: 6.5.4 | C25: Cooperation on water security Cooperate with local, regional, national, or global governments on water security.
C26: Local
C27: Regional
C28: National
A29: Indicator | B29: 6.5.5 | C29: Promoting conscious water usage on campus Actively promote conscious water usage on campus,
A30: Indicator | B30: 6.5.6 | C30: Promoting conscious water usage in the wider community. Actively promote conscious water usage in the wider community

Sheet SDG7
B1: SDG7: Affordable and Clean Energy
A2: Type | B2: Metric and indicator reference | C2: Metric / Indicator | D2: Value (for continuous data) | E2: Yes/No | F2: Evidence1 | G2: Public (Yes/No)
A3: Metric | B3: 7.2 | C3: University measures towards affordable and clean energy
A4: Indicator | B4: 7.2.1 | C4: Energy-efficient renovation and building Have a policy in place for ensuring all renovations or new builds are following energy efficiency standards
A5: Indicator | B5: 7.2.2 | C5: Upgrade buildings to higher energy efficiency Have plans to upgrade existing buildings to higher energy efficiency
A6: Indicator | B6: 7.2.3 | C6: Carbon reduction and emission reduction process Have a process for carbon management and reducing carbon dioxide emissions
A7: Indicator | B7: 7.2.4 | C7: Plan to reduce energy consumption Have an energy efficiency plan in place to reduce overall energy consumption
A8: Indicator | B8: 7.2.5 | C8: Energy wastage identification Undergo energy reviews to identify areas where energy waste is highest
A9: Indicator | B9: 7.2.6 | C9: Divestment policy Have a policy on divesting investments from carbon-intensive energy industries notably coal and oil
A10: Metric | B10: 7.3 | C10: Energy use density
A11: Indicator | B11: 7.3.1 | C11: Energy usage per sqm
C12: Total energy used
C13: University floor space
A14: Metric | B14: 7.4 | C14: Energy and the community
A15: Indicator | B15: 7.4.1 | C15: Local community outreach for energy efficiency Provide programmes for local community to learn about importance of energy efficiency and clean energy
A16: Indicator | B16: 7.4.2 | C16: 100% renewable energy pledge Promote a public pledge toward 100% renewable energy beyond the university
A17: Indicator | B17: 7.4.3 | C17: Energy efficiency services for industry Provide direct services to local industry aimed at improving energy efficiency and clean energy (energy efficiency assessments, workshops, research renewable energy options)
C18: Free
C19: Paid
A20: Indicator | B20: 7.4.4 | C20: Policy development for clean energy technology Inform and support governments in clean energy and energy-efficient technology policy development
C21: Local
C22: Regional
C23: National
C24: Global
A25: Indicator | B25: 7.4.5 | C25: Assistance to low-carbon innovation Provide assistance for start-ups that foster and support a low-carbon economy or technology
B26: 7.5 | C26: Low-carbon energy use
C27: Total energy used
C28: Total energy used from low-carbon sources

Sheet SDG8
A1: SDG8: Decent Work and Economic Growth
A2: Type | B2: Metric and indicator reference | C2: Metric / Indicator | D2: Value (for continuous data) | E2: Yes/No | F2: Evidence1 | G2: Public (Yes/No)
A3: Metric | B3: 8.2 | C3: Employment practice
A4: Indicator | B4: 8.2.1 | C4: Employment practice living wage Pay all staff and faculty at least the living wage, defined as the local living wage (if government defines this) or the local financial poverty indicator for a family of four (expressed as an hourly wage)
A5: Indicator | B5: 8.2.2 | C5: Employment practice unions Recognize unions (freedom of association & collective bargaining) for all, including women & international staff
A6: Indicator | B6: 8.2.3 | C6: Employment policy on discrimination Have a policy on ending discrimination in the workplace (including discrimination based on religion, sexuality, gender, age, or refugee status)
A7: Indicator | B7: 8.2.4 | C7: Employment policy modern slavery Have a policy commitment against forced labour, modern slavery, human trafficking and child labour
A8: Indicator | B8: 8.2.5 | C8: Employment practice equivalent rights outsourcing Have a policy on guaranteeing equivalent rights of workers when outsourcing activities to third parties
A9: Indicator | B9: 8.2.6 | C9: Employment policy pay scale equity Have a policy on pay scale equity including a commitment to measurement and elimination of gender pay gaps
A10: Indicator | B10: 8.2.7 | C10: Tracking pay scale for gender equity Measurement or tracking pay scale gender equity
A11: Indicator | B11: 8.2.8 | C11: Employment practice appeal process Have a process for employees to appeal on employee rights and/or pay
A12: Indicator | B12: 8.2.9 | C12: Employment practice labour rights Recognise labour rights (freedom of association and collective bargaining) for all, including women and international staff
A13: Metric | B13: 8.3 | C13: Expenditure per employee
A14: Indicator | B14: 8.3.1 | C14: Expenditure per employee
C15: Number of employees
C16: University expenditure
A17: Metric | B17: 8.4 | C17: Proportion of students taking work placements
A18: Indicator | B18: 8.4.1 | C18: Proportion of students with work placements
C19: Number of students
C20: Number of students with work placements for more than a month
A21: Metric | B21: 8.5 | C21: Proportion of employees on secure contracts
A22: Indicator | B22: 8.5.1 | C22: Proportion of employees on secure contracts
C23: Number of employees
C24: Number of employees on contracts of over 24 months

Sheet SDG9
A1: SDG9: Industry, Innovation and Infrastructure
A2: Type | B2: Metric and indicator reference | C2: Metric / Indicator | D2: Value (for continuous data) | E2: Yes/No | F2: Evidence1 | G2: Public (Yes/No)
A3: Metric | B3: 9.3 | C3: University spin offs
A4: Indicator | B4: 9.3.1 | C4: Number of university spin offs
C5: Number of university spin-offs
A6: Metric | B6: 9.4 | C6: Research income from industry and commerce
A7: Indicator | B7: 9.4.1 | C7: Research income from industry and commerce per academic staff
C8: Research income from industry and commerce by subject area: STEM
C9: Research income from industry and commerce by subject area: Medicine
C10: Research income from industry and commerce by subject area: Arts & Humanities / Social sciences
C11: Number of academic staff by subject area: STEM
C12: Number of academic staff by subject area: Medicine
C13: Number of academic staff by subject area: Arts & Humanities / Social sciences

Sheet SDG10
A1: SDG10: Reduced Inequalities | K1: Gestión interna UDES 2026
A2: Type | B2: Metric and indicator reference | C2: Metric / Indicator | D2: Metrica / Indicador Este año solicitamos información del año académico 2024. | E2: Fuente datos | F2: Value (for continuous data) | G2: Yes/No | H2: Evidence1 | I2: Public (Yes/No) | J2: Comentarios" con una longitud máxima de 1000 caracteres | K2: Coordinación del reporte | L2: Responsable / fuente principal | M2: Dependencia(s) de apoyo | N2: Tipo de requerimiento | O2: Peso oficial THE | P2: Prioridad | Q2: Estado
A3: Metric | B3: 10.2 | C3: First-generation students | D3: Estudiantes de primera generación | E3: Planeación Institucional | K3: Planeación Institucional | L3: Planeación Institucional | M3: Registro y Control Académico | N3: Métrica / bloque de evaluación | O3: 0.155 | P3: =IF(ISBLANK(O3),"",IF(O3=0,"Baja",IF(OR(O3>=10%,ISNUMBER(SEARCH("Política",N3))),"Alta","Media"))) -> Alta | Q3: Pendiente
A4: Indicator | B4: 10.2.1 | C4: Proportion of first-generation students | D4: Proporción de estudiantes de primera generación | K4: Planeación Institucional | L4: Planeación Institucional | M4: Registro y Control Académico | N4: Dato cuantitativo 2024 | O4: 0.155 | P4: =IF(ISBLANK(O4),"",IF(O4=0,"Baja",IF(OR(O4>=10%,ISNUMBER(SEARCH("Política",N4))),"Alta","Media"))) -> Alta | Q4: Pendiente
C5: Number of students starting a degree | D5: Número de estudiantes que inician una carrera | K5: Planeación Institucional | L5: Planeación Institucional | M5: Registro y Control Académico | N5: Dato cuantitativo 2024
C6: Number of first-generation students starting a degree | D6: Número de estudiantes de primera generación que comienzan una carrera | K6: Planeación Institucional | L6: Planeación Institucional | M6: Registro y Control Académico | N6: Dato cuantitativo 2024
A7: Metric | B7: 10.3 | C7: International students from developing countries | D7: Estudiantes internacionales de países en desarrollo | E7: Planeación Institucional DRNI | K7: Planeación Institucional | L7: Planeación Institucional | M7: DRNI | N7: Métrica / bloque de evaluación | O7: 0.155 | P7: =IF(ISBLANK(O7),"",IF(O7=0,"Baja",IF(OR(O7>=10%,ISNUMBER(SEARCH("Política",N7))),"Alta","Media"))) -> Alta | Q7: Pendiente
A8: Indicator | B8: 10.3.1 | C8: Proportion of international students from developing countries | D8: Proporción de estudiantes internacionales de países en desarrollo | K8: Planeación Institucional | L8: Planeación Institucional | M8: DRNI | N8: Dato cuantitativo 2024 | O8: 0.155 | P8: =IF(ISBLANK(O8),"",IF(O8=0,"Baja",IF(OR(O8>=10%,ISNUMBER(SEARCH("Política",N8))),"Alta","Media"))) -> Alta | Q8: Pendiente
C9: Number of students | D9: Número de estudiantes | K9: Planeación Institucional | L9: Planeación Institucional | M9: DRNI | N9: Dato cuantitativo 2024
C10: Number of international students from developing countries | D10: Número de estudiantes internacionales de países en desarrollo | K10: Planeación Institucional | L10: Planeación Institucional | M10: DRNI | N10: Dato cuantitativo 2024
A11: Metric | B11: 10.4 | C11: Proportion of students with disabilities | D11: Proporción de estudiantes con discapacidad | E11: Planeación Institucional | K11: Planeación Institucional | L11: Planeación Institucional | M11: Bienestar / Desarrollo Estudiantil | N11: Métrica / bloque de evaluación | O11: 0.115 | P11: =IF(ISBLANK(O11),"",IF(O11=0,"Baja",IF(OR(O11>=10%,ISNUMBER(SEARCH("Política",N11))),"Alta","Media"))) -> Alta | Q11: Pendiente
A12: Indicator | B12: 10.4.1 | C12: Proportion of students with disabilities | D12: Proporción de estudiantes con discapacidad | K12: Planeación Institucional | L12: Planeación Institucional | M12: Bienestar / Desarrollo Estudiantil | N12: Dato cuantitativo 2024 | O12: 0.115 | P12: =IF(ISBLANK(O12),"",IF(O12=0,"Baja",IF(OR(O12>=10%,ISNUMBER(SEARCH("Política",N12))),"Alta","Media"))) -> Alta | Q12: Pendiente
C13: Number of students | D13: Número de estudiantes | K13: Planeación Institucional | L13: Planeación Institucional | M13: Bienestar / Desarrollo Estudiantil | N13: Dato cuantitativo 2024
C14: Number of students with disability | D14: Número de estudiantes con discapacidad | K14: Planeación Institucional | L14: Planeación Institucional | M14: Bienestar / Desarrollo Estudiantil | N14: Dato cuantitativo 2024
A15: Metric | B15: 10.5 | C15: Proportion of employees with disabilities | D15: Proporción de empleados con discapacidad | E15: Talento Humano | K15: Planeación Institucional | L15: Talento Humano | M15: Planeación Institucional | N15: Métrica / bloque de evaluación | O15: 0.115 | P15: =IF(ISBLANK(O15),"",IF(O15=0,"Baja",IF(OR(O15>=10%,ISNUMBER(SEARCH("Política",N15))),"Alta","Media"))) -> Alta | Q15: Pendiente
